Unhandled exception in client_connected_cb
transport: <_SelectorSocketTransport fd=7 read=polling write=<idle, bufsize=0>>
Traceback (most recent call last):
  File "/opt/homebrew/anaconda3/lib/python3.12/site-packages/anyio/_core/_tasks.py", line 115, in fail_after
    yield cancel_scope
  File "/opt/homebrew/anaconda3/lib/python3.12/site-packages/httpcore/_backends/anyio.py", line 34, in read
    return await self._stream.receive(max_bytes=max_bytes)
           ^^^^^^^^^^^^^^^^^^^^^^^^^^^^^^^^^^^^^^^^^^^^^^^
  File "/opt/homebrew/anaconda3/lib/python3.12/site-packages/anyio/_backends/_asyncio.py", line 1123, in receive
    await self._protocol.read_event.wait()
  File "/opt/homebrew/anaconda3/lib/python3.12/asyncio/locks.py", line 212, in wait
    await fut
asyncio.exceptions.CancelledError: Cancelled by cancel scope 102c8f7a0

During handling of the above exception, another exception occurred:

Traceback (most recent call last):
  File "/opt/homebrew/anaconda3/lib/python3.12/site-packages/httpcore/_exceptions.py", line 10, in map_exceptions
    yield
  File "/opt/homebrew/anaconda3/lib/python3.12/site-packages/httpcore/_backends/anyio.py", line 32, in read
    with anyio.fail_after(timeout):
  File "/opt/homebrew/anaconda3/lib/python3.12/contextlib.py", line 158, in __exit__
    self.gen.throw(value)
  File "/opt/homebrew/anaconda3/lib/python3.12/site-packages/anyio/_core/_tasks.py", line 118, in fail_after
    raise TimeoutError
TimeoutError

The above exception was the direct cause of the following exception:

Traceback (most recent call last):
  File "/opt/homebrew/anaconda3/lib/python3.12/site-packages/httpx/_transports/default.py", line 67, in map_httpcore_exceptions
    yield
  File "/opt/homebrew/anaconda3/lib/python3.12/site-packages/httpx/_transports/default.py", line 371, in handle_async_request
    resp = await self._pool.handle_async_request(req)
           ^^^^^^^^^^^^^^^^^^^^^^^^^^^^^^^^^^^^^^^^^^
  File "/opt/homebrew/anaconda3/lib/python3.12/site-packages/httpcore/_async/connection_pool.py", line 268, in handle_async_request
    raise exc
  File "/opt/homebrew/anaconda3/lib/python3.12/site-packages/httpcore/_async/connection_pool.py", line 251, in handle_async_request
    response = await connection.handle_async_request(request)
               ^^^^^^^^^^^^^^^^^^^^^^^^^^^^^^^^^^^^^^^^^^^^^^
  File "/opt/homebrew/anaconda3/lib/python3.12/site-packages/httpcore/_async/connection.py", line 103, in handle_async_request
    return await self._connection.handle_async_request(request)
           ^^^^^^^^^^^^^^^^^^^^^^^^^^^^^^^^^^^^^^^^^^^^^^^^^^^^
  File "/opt/homebrew/anaconda3/lib/python3.12/site-packages/httpcore/_async/http11.py", line 133, in handle_async_request
    raise exc
  File "/opt/homebrew/anaconda3/lib/python3.12/site-packages/httpcore/_async/http11.py", line 111, in handle_async_request
    ) = await self._receive_response_headers(**kwargs)
        ^^^^^^^^^^^^^^^^^^^^^^^^^^^^^^^^^^^^^^^^^^^^^^
  File "/opt/homebrew/anaconda3/lib/python3.12/site-packages/httpcore/_async/http11.py", line 176, in _receive_response_headers
    event = await self._receive_event(timeout=timeout)
            ^^^^^^^^^^^^^^^^^^^^^^^^^^^^^^^^^^^^^^^^^^
  File "/opt/homebrew/anaconda3/lib/python3.12/site-packages/httpcore/_async/http11.py", line 212, in _receive_event
    data = await self._network_stream.read(
           ^^^^^^^^^^^^^^^^^^^^^^^^^^^^^^^^
  File "/opt/homebrew/anaconda3/lib/python3.12/site-packages/httpcore/_backends/anyio.py", line 31, in read
    with map_exceptions(exc_map):
  File "/opt/homebrew/anaconda3/lib/python3.12/contextlib.py", line 158, in __exit__
    self.gen.throw(value)
  File "/opt/homebrew/anaconda3/lib/python3.12/site-packages/httpcore/_exceptions.py", line 14, in map_exceptions
    raise to_exc(exc) from exc
httpcore.ReadTimeout

The above exception was the direct cause of the following exception:

Traceback (most recent call last):
  File "/Users/matthewkweon/Documents/GitHub/P2P/src/p2p_chat/server.py", line 58, in handle_client
    stored_msgs = await get_stored_messages(username, api_base)
                  ^^^^^^^^^^^^^^^^^^^^^^^^^^^^^^^^^^^^^^^^^^^^^
  File "/Users/matthewkweon/Documents/GitHub/P2P/src/p2p_chat/server.py", line 33, in get_stored_messages
    response = await client.get(f"{api_base}/messages/{username}")
               ^^^^^^^^^^^^^^^^^^^^^^^^^^^^^^^^^^^^^^^^^^^^^^^^^^^
  File "/opt/homebrew/anaconda3/lib/python3.12/site-packages/httpx/_client.py", line 1786, in get
    return await self.request(
           ^^^^^^^^^^^^^^^^^^^
  File "/opt/homebrew/anaconda3/lib/python3.12/site-packages/httpx/_client.py", line 1559, in request
    return await self.send(request, auth=auth, follow_redirects=follow_redirects)
           ^^^^^^^^^^^^^^^^^^^^^^^^^^^^^^^^^^^^^^^^^^^^^^^^^^^^^^^^^^^^^^^^^^^^^^
  File "/opt/homebrew/anaconda3/lib/python3.12/site-packages/httpx/_client.py", line 1646, in send
    response = await self._send_handling_auth(
               ^^^^^^^^^^^^^^^^^^^^^^^^^^^^^^^
  File "/opt/homebrew/anaconda3/lib/python3.12/site-packages/httpx/_client.py", line 1674, in _send_handling_auth
    response = await self._send_handling_redirects(
               ^^^^^^^^^^^^^^^^^^^^^^^^^^^^^^^^^^^^
  File "/opt/homebrew/anaconda3/lib/python3.12/site-packages/httpx/_client.py", line 1711, in _send_handling_redirects
    response = await self._send_single_request(request)
               ^^^^^^^^^^^^^^^^^^^^^^^^^^^^^^^^^^^^^^^^
  File "/opt/homebrew/anaconda3/lib/python3.12/site-packages/httpx/_client.py", line 1748, in _send_single_request
    response = await transport.handle_async_request(request)
               ^^^^^^^^^^^^^^^^^^^^^^^^^^^^^^^^^^^^^^^^^^^^^
  File "/opt/homebrew/anaconda3/lib/python3.12/site-packages/httpx/_transports/default.py", line 370, in handle_async_request
    with map_httpcore_exceptions():
  File "/opt/homebrew/anaconda3/lib/python3.12/contextlib.py", line 158, in __exit__
    self.gen.throw(value)
  File "/opt/homebrew/anaconda3/lib/python3.12/site-packages/httpx/_transports/default.py", line 84, in map_httpcore_exceptions
    raise mapped_exc(message) from exc
httpx.ReadTimeout
Unhandled exception in client_connected_cb
transport: <_SelectorSocketTransport fd=8 read=polling write=<idle, bufsize=0>>
Traceback (most recent call last):
  File "/opt/homebrew/anaconda3/lib/python3.12/site-packages/anyio/_core/_tasks.py", line 115, in fail_after
    yield cancel_scope
  File "/opt/homebrew/anaconda3/lib/python3.12/site-packages/httpcore/_backends/anyio.py", line 34, in read
    return await self._stream.receive(max_bytes=max_bytes)
           ^^^^^^^^^^^^^^^^^^^^^^^^^^^^^^^^^^^^^^^^^^^^^^^
  File "/opt/homebrew/anaconda3/lib/python3.12/site-packages/anyio/_backends/_asyncio.py", line 1123, in receive
    await self._protocol.read_event.wait()
  File "/opt/homebrew/anaconda3/lib/python3.12/asyncio/locks.py", line 212, in wait
    await fut
asyncio.exceptions.CancelledError: Cancelled by cancel scope 102c8ecc0

During handling of the above exception, another exception occurred:

Traceback (most recent call last):
  File "/opt/homebrew/anaconda3/lib/python3.12/site-packages/httpcore/_exceptions.py", line 10, in map_exceptions
    yield
  File "/opt/homebrew/anaconda3/lib/python3.12/site-packages/httpcore/_backends/anyio.py", line 32, in read
    with anyio.fail_after(timeout):
  File "/opt/homebrew/anaconda3/lib/python3.12/contextlib.py", line 158, in __exit__
    self.gen.throw(value)
  File "/opt/homebrew/anaconda3/lib/python3.12/site-packages/anyio/_core/_tasks.py", line 118, in fail_after
    raise TimeoutError
TimeoutError

The above exception was the direct cause of the following exception:

Traceback (most recent call last):
  File "/opt/homebrew/anaconda3/lib/python3.12/site-packages/httpx/_transports/default.py", line 67, in map_httpcore_exceptions
    yield
  File "/opt/homebrew/anaconda3/lib/python3.12/site-packages/httpx/_transports/default.py", line 371, in handle_async_request
    resp = await self._pool.handle_async_request(req)
           ^^^^^^^^^^^^^^^^^^^^^^^^^^^^^^^^^^^^^^^^^^
  File "/opt/homebrew/anaconda3/lib/python3.12/site-packages/httpcore/_async/connection_pool.py", line 268, in handle_async_request
    raise exc
  File "/opt/homebrew/anaconda3/lib/python3.12/site-packages/httpcore/_async/connection_pool.py", line 251, in handle_async_request
    response = await connection.handle_async_request(request)
               ^^^^^^^^^^^^^^^^^^^^^^^^^^^^^^^^^^^^^^^^^^^^^^
  File "/opt/homebrew/anaconda3/lib/python3.12/site-packages/httpcore/_async/connection.py", line 103, in handle_async_request
    return await self._connection.handle_async_request(request)
           ^^^^^^^^^^^^^^^^^^^^^^^^^^^^^^^^^^^^^^^^^^^^^^^^^^^^
  File "/opt/homebrew/anaconda3/lib/python3.12/site-packages/httpcore/_async/http11.py", line 133, in handle_async_request
    raise exc
  File "/opt/homebrew/anaconda3/lib/python3.12/site-packages/httpcore/_async/http11.py", line 111, in handle_async_request
    ) = await self._receive_response_headers(**kwargs)
        ^^^^^^^^^^^^^^^^^^^^^^^^^^^^^^^^^^^^^^^^^^^^^^
  File "/opt/homebrew/anaconda3/lib/python3.12/site-packages/httpcore/_async/http11.py", line 176, in _receive_response_headers
    event = await self._receive_event(timeout=timeout)
            ^^^^^^^^^^^^^^^^^^^^^^^^^^^^^^^^^^^^^^^^^^
  File "/opt/homebrew/anaconda3/lib/python3.12/site-packages/httpcore/_async/http11.py", line 212, in _receive_event
    data = await self._network_stream.read(
           ^^^^^^^^^^^^^^^^^^^^^^^^^^^^^^^^
  File "/opt/homebrew/anaconda3/lib/python3.12/site-packages/httpcore/_backends/anyio.py", line 31, in read
    with map_exceptions(exc_map):
  File "/opt/homebrew/anaconda3/lib/python3.12/contextlib.py", line 158, in __exit__
    self.gen.throw(value)
  File "/opt/homebrew/anaconda3/lib/python3.12/site-packages/httpcore/_exceptions.py", line 14, in map_exceptions
    raise to_exc(exc) from exc
httpcore.ReadTimeout

The above exception was the direct cause of the following exception:

Traceback (most recent call last):
  File "/Users/matthewkweon/Documents/GitHub/P2P/src/p2p_chat/server.py", line 58, in handle_client
    stored_msgs = await get_stored_messages(username, api_base)
                  ^^^^^^^^^^^^^^^^^^^^^^^^^^^^^^^^^^^^^^^^^^^^^
  File "/Users/matthewkweon/Documents/GitHub/P2P/src/p2p_chat/server.py", line 33, in get_stored_messages
    response = await client.get(f"{api_base}/messages/{username}")
               ^^^^^^^^^^^^^^^^^^^^^^^^^^^^^^^^^^^^^^^^^^^^^^^^^^^
  File "/opt/homebrew/anaconda3/lib/python3.12/site-packages/httpx/_client.py", line 1786, in get
    return await self.request(
           ^^^^^^^^^^^^^^^^^^^
  File "/opt/homebrew/anaconda3/lib/python3.12/site-packages/httpx/_client.py", line 1559, in request
    return await self.send(request, auth=auth, follow_redirects=follow_redirects)
           ^^^^^^^^^^^^^^^^^^^^^^^^^^^^^^^^^^^^^^^^^^^^^^^^^^^^^^^^^^^^^^^^^^^^^^
  File "/opt/homebrew/anaconda3/lib/python3.12/site-packages/httpx/_client.py", line 1646, in send
    response = await self._send_handling_auth(
               ^^^^^^^^^^^^^^^^^^^^^^^^^^^^^^^
  File "/opt/homebrew/anaconda3/lib/python3.12/site-packages/httpx/_client.py", line 1674, in _send_handling_auth
    response = await self._send_handling_redirects(
               ^^^^^^^^^^^^^^^^^^^^^^^^^^^^^^^^^^^^
  File "/opt/homebrew/anaconda3/lib/python3.12/site-packages/httpx/_client.py", line 1711, in _send_handling_redirects
    response = await self._send_single_request(request)
               ^^^^^^^^^^^^^^^^^^^^^^^^^^^^^^^^^^^^^^^^
  File "/opt/homebrew/anaconda3/lib/python3.12/site-packages/httpx/_client.py", line 1748, in _send_single_request
    response = await transport.handle_async_request(request)
               ^^^^^^^^^^^^^^^^^^^^^^^^^^^^^^^^^^^^^^^^^^^^^
  File "/opt/homebrew/anaconda3/lib/python3.12/site-packages/httpx/_transports/default.py", line 370, in handle_async_request
    with map_httpcore_exceptions():
  File "/opt/homebrew/anaconda3/lib/python3.12/contextlib.py", line 158, in __exit__
    self.gen.throw(value)
  File "/opt/homebrew/anaconda3/lib/python3.12/site-packages/httpx/_transports/default.py", line 84, in map_httpcore_exceptions
    raise mapped_exc(message) from exc
httpx.ReadTimeout
Unhandled exception in client_connected_cb
transport: <_SelectorSocketTransport fd=11 read=idle write=<idle, bufsize=0>>
Traceback (most recent call last):
  File "/opt/homebrew/anaconda3/lib/python3.12/site-packages/anyio/_core/_tasks.py", line 115, in fail_after
    yield cancel_scope
  File "/opt/homebrew/anaconda3/lib/python3.12/site-packages/httpcore/_backends/anyio.py", line 34, in read
    return await self._stream.receive(max_bytes=max_bytes)
           ^^^^^^^^^^^^^^^^^^^^^^^^^^^^^^^^^^^^^^^^^^^^^^^
  File "/opt/homebrew/anaconda3/lib/python3.12/site-packages/anyio/_backends/_asyncio.py", line 1123, in receive
    await self._protocol.read_event.wait()
  File "/opt/homebrew/anaconda3/lib/python3.12/asyncio/locks.py", line 212, in wait
    await fut
asyncio.exceptions.CancelledError: Cancelled by cancel scope 102e00500

During handling of the above exception, another exception occurred:

Traceback (most recent call last):
  File "/opt/homebrew/anaconda3/lib/python3.12/site-packages/httpcore/_exceptions.py", line 10, in map_exceptions
    yield
  File "/opt/homebrew/anaconda3/lib/python3.12/site-packages/httpcore/_backends/anyio.py", line 32, in read
    with anyio.fail_after(timeout):
  File "/opt/homebrew/anaconda3/lib/python3.12/contextlib.py", line 158, in __exit__
    self.gen.throw(value)
  File "/opt/homebrew/anaconda3/lib/python3.12/site-packages/anyio/_core/_tasks.py", line 118, in fail_after
    raise TimeoutError
TimeoutError

The above exception was the direct cause of the following exception:

Traceback (most recent call last):
  File "/opt/homebrew/anaconda3/lib/python3.12/site-packages/httpx/_transports/default.py", line 67, in map_httpcore_exceptions
    yield
  File "/opt/homebrew/anaconda3/lib/python3.12/site-packages/httpx/_transports/default.py", line 371, in handle_async_request
    resp = await self._pool.handle_async_request(req)
           ^^^^^^^^^^^^^^^^^^^^^^^^^^^^^^^^^^^^^^^^^^
  File "/opt/homebrew/anaconda3/lib/python3.12/site-packages/httpcore/_async/connection_pool.py", line 268, in handle_async_request
    raise exc
  File "/opt/homebrew/anaconda3/lib/python3.12/site-packages/httpcore/_async/connection_pool.py", line 251, in handle_async_request
    response = await connection.handle_async_request(request)
               ^^^^^^^^^^^^^^^^^^^^^^^^^^^^^^^^^^^^^^^^^^^^^^
  File "/opt/homebrew/anaconda3/lib/python3.12/site-packages/httpcore/_async/connection.py", line 103, in handle_async_request
    return await self._connection.handle_async_request(request)
           ^^^^^^^^^^^^^^^^^^^^^^^^^^^^^^^^^^^^^^^^^^^^^^^^^^^^
  File "/opt/homebrew/anaconda3/lib/python3.12/site-packages/httpcore/_async/http11.py", line 133, in handle_async_request
    raise exc
  File "/opt/homebrew/anaconda3/lib/python3.12/site-packages/httpcore/_async/http11.py", line 111, in handle_async_request
    ) = await self._receive_response_headers(**kwargs)
        ^^^^^^^^^^^^^^^^^^^^^^^^^^^^^^^^^^^^^^^^^^^^^^
  File "/opt/homebrew/anaconda3/lib/python3.12/site-packages/httpcore/_async/http11.py", line 176, in _receive_response_headers
    event = await self._receive_event(timeout=timeout)
            ^^^^^^^^^^^^^^^^^^^^^^^^^^^^^^^^^^^^^^^^^^
  File "/opt/homebrew/anaconda3/lib/python3.12/site-packages/httpcore/_async/http11.py", line 212, in _receive_event
    data = await self._network_stream.read(
           ^^^^^^^^^^^^^^^^^^^^^^^^^^^^^^^^
  File "/opt/homebrew/anaconda3/lib/python3.12/site-packages/httpcore/_backends/anyio.py", line 31, in read
    with map_exceptions(exc_map):
  File "/opt/homebrew/anaconda3/lib/python3.12/contextlib.py", line 158, in __exit__
    self.gen.throw(value)
  File "/opt/homebrew/anaconda3/lib/python3.12/site-packages/httpcore/_exceptions.py", line 14, in map_exceptions
    raise to_exc(exc) from exc
httpcore.ReadTimeout

The above exception was the direct cause of the following exception:

Traceback (most recent call last):
  File "/Users/matthewkweon/Documents/GitHub/P2P/src/p2p_chat/server.py", line 58, in handle_client
    stored_msgs = await get_stored_messages(username, api_base)
                  ^^^^^^^^^^^^^^^^^^^^^^^^^^^^^^^^^^^^^^^^^^^^^
  File "/Users/matthewkweon/Documents/GitHub/P2P/src/p2p_chat/server.py", line 33, in get_stored_messages
    response = await client.get(f"{api_base}/messages/{username}")
               ^^^^^^^^^^^^^^^^^^^^^^^^^^^^^^^^^^^^^^^^^^^^^^^^^^^
  File "/opt/homebrew/anaconda3/lib/python3.12/site-packages/httpx/_client.py", line 1786, in get
    return await self.request(
           ^^^^^^^^^^^^^^^^^^^
  File "/opt/homebrew/anaconda3/lib/python3.12/site-packages/httpx/_client.py", line 1559, in request
    return await self.send(request, auth=auth, follow_redirects=follow_redirects)
           ^^^^^^^^^^^^^^^^^^^^^^^^^^^^^^^^^^^^^^^^^^^^^^^^^^^^^^^^^^^^^^^^^^^^^^
  File "/opt/homebrew/anaconda3/lib/python3.12/site-packages/httpx/_client.py", line 1646, in send
    response = await self._send_handling_auth(
               ^^^^^^^^^^^^^^^^^^^^^^^^^^^^^^^
  File "/opt/homebrew/anaconda3/lib/python3.12/site-packages/httpx/_client.py", line 1674, in _send_handling_auth
    response = await self._send_handling_redirects(
               ^^^^^^^^^^^^^^^^^^^^^^^^^^^^^^^^^^^^
  File "/opt/homebrew/anaconda3/lib/python3.12/site-packages/httpx/_client.py", line 1711, in _send_handling_redirects
    response = await self._send_single_request(request)
               ^^^^^^^^^^^^^^^^^^^^^^^^^^^^^^^^^^^^^^^^
  File "/opt/homebrew/anaconda3/lib/python3.12/site-packages/httpx/_client.py", line 1748, in _send_single_request
    response = await transport.handle_async_request(request)
               ^^^^^^^^^^^^^^^^^^^^^^^^^^^^^^^^^^^^^^^^^^^^^
  File "/opt/homebrew/anaconda3/lib/python3.12/site-packages/httpx/_transports/default.py", line 370, in handle_async_request
    with map_httpcore_exceptions():
  File "/opt/homebrew/anaconda3/lib/python3.12/contextlib.py", line 158, in __exit__
    self.gen.throw(value)
  File "/opt/homebrew/anaconda3/lib/python3.12/site-packages/httpx/_transports/default.py", line 84, in map_httpcore_exceptions
    raise mapped_exc(message) from exc
httpx.ReadTimeout
Server running on ('127.0.0.1', 5000)
Using API at http://127.0.0.1:8000
thermometer1 connected.
openai connected.
matt connected.
Traceback (most recent call last):
  File "/opt/homebrew/anaconda3/lib/python3.12/asyncio/runners.py", line 118, in run
    return self._loop.run_until_complete(task)
           ^^^^^^^^^^^^^^^^^^^^^^^^^^^^^^^^^^^
  File "/opt/homebrew/anaconda3/lib/python3.12/asyncio/base_events.py", line 687, in run_until_complete
    return future.result()
           ^^^^^^^^^^^^^^^
  File "/Users/matthewkweon/Documents/GitHub/P2P/src/p2p_chat/server.py", line 119, in run_server
    await server.serve_forever()
  File "/opt/homebrew/anaconda3/lib/python3.12/asyncio/base_events.py", line 371, in serve_forever
    await self._serving_forever_fut
asyncio.exceptions.CancelledError

During handling of the above exception, another exception occurred:

Traceback (most recent call last):
  File "/Users/matthewkweon/Documents/GitHub/P2P/src/p2p_chat/server.py", line 136, in <module>
    main_entry()
  File "/Users/matthewkweon/Documents/GitHub/P2P/src/p2p_chat/server.py", line 133, in main_entry
    main(args.host, args.port, args.api_base)
  File "/Users/matthewkweon/Documents/GitHub/P2P/src/p2p_chat/server.py", line 123, in main
    asyncio.run(run_server(host, port, api_base))
  File "/opt/homebrew/anaconda3/lib/python3.12/asyncio/runners.py", line 194, in run
    return runner.run(main)
           ^^^^^^^^^^^^^^^^
  File "/opt/homebrew/anaconda3/lib/python3.12/asyncio/runners.py", line 123, in run
    raise KeyboardInterrupt()
KeyboardInterrupt
