Starting thermometer service as 'thermometer1'
Connecting to chat server at 127.0.0.1:5000
Using API at http://127.0.0.1:8000
Broadcasting temperature every 100 seconds
[THERMOMETER] Received raw message: Connected! Users online: thermometer1
Traceback (most recent call last):
  File "/opt/homebrew/anaconda3/lib/python3.12/asyncio/runners.py", line 118, in run
    return self._loop.run_until_complete(task)
           ^^^^^^^^^^^^^^^^^^^^^^^^^^^^^^^^^^^
  File "/opt/homebrew/anaconda3/lib/python3.12/asyncio/base_events.py", line 687, in run_until_complete
    return future.result()
           ^^^^^^^^^^^^^^^
  File "/Users/matthewkweon/Documents/GitHub/P2P/src/p2p_chat/services/thermometer.py", line 100, in run_thermometer
    await asyncio.gather(
  File "/Users/matthewkweon/Documents/GitHub/P2P/src/p2p_chat/services/thermometer.py", line 91, in broadcast_temperature
    await asyncio.sleep(interval)  # Broadcast interval
    ^^^^^^^^^^^^^^^^^^^^^^^^^^^^^
  File "/opt/homebrew/anaconda3/lib/python3.12/asyncio/tasks.py", line 665, in sleep
    return await future
           ^^^^^^^^^^^^
asyncio.exceptions.CancelledError

During handling of the above exception, another exception occurred:

Traceback (most recent call last):
  File "/Users/matthewkweon/Documents/GitHub/P2P/src/p2p_chat/services/thermometer.py", line 127, in <module>
    main_entry()
  File "/Users/matthewkweon/Documents/GitHub/P2P/src/p2p_chat/services/thermometer.py", line 124, in main_entry
    main(args.host, args.port, args.username, args.api_base, args.interval)
  File "/Users/matthewkweon/Documents/GitHub/P2P/src/p2p_chat/services/thermometer.py", line 112, in main
    asyncio.run(run_thermometer(host, port, username, api_base, interval))
  File "/opt/homebrew/anaconda3/lib/python3.12/asyncio/runners.py", line 194, in run
    return runner.run(main)
           ^^^^^^^^^^^^^^^^
  File "/opt/homebrew/anaconda3/lib/python3.12/asyncio/runners.py", line 123, in run
    raise KeyboardInterrupt()
KeyboardInterrupt
